[2021-08-22 14:48:43,646] {taskinstance.py:896} INFO - Dependencies all met for <TaskInstance: download_rocket_launches.get_pictures 2021-08-08T00:00:00+00:00 [queued]>
[2021-08-22 14:48:43,837] {taskinstance.py:896} INFO - Dependencies all met for <TaskInstance: download_rocket_launches.get_pictures 2021-08-08T00:00:00+00:00 [queued]>
[2021-08-22 14:48:43,837] {taskinstance.py:1087} INFO - 
--------------------------------------------------------------------------------
[2021-08-22 14:48:43,837] {taskinstance.py:1088} INFO - Starting attempt 1 of 1
[2021-08-22 14:48:43,838] {taskinstance.py:1089} INFO - 
--------------------------------------------------------------------------------
[2021-08-22 14:48:43,962] {taskinstance.py:1107} INFO - Executing <Task(PythonOperator): get_pictures> on 2021-08-08T00:00:00+00:00
[2021-08-22 14:48:44,027] {standard_task_runner.py:76} INFO - Running: ['***', 'tasks', 'run', 'download_rocket_launches', 'get_pictures', '2021-08-08T00:00:00+00:00', '--job-id', '34', '--pool', 'default_pool', '--raw', '--subdir', 'DAGS_FOLDER/1.rocket_launch_data.py', '--cfg-path', '/tmp/tmp8du_rnyi', '--error-file', '/tmp/tmpwaatq3rw']
[2021-08-22 14:48:44,041] {standard_task_runner.py:77} INFO - Job 34: Subtask get_pictures
[2021-08-22 14:48:43,994] {standard_task_runner.py:52} INFO - Started process 93 to run task
[2021-08-22 14:48:44,342] {logging_mixin.py:104} INFO - Running <TaskInstance: download_rocket_launches.get_pictures 2021-08-08T00:00:00+00:00 [running]> on host b4dfeeeb641c
[2021-08-22 14:48:44,857] {taskinstance.py:1302} INFO - Exporting the following env vars:
AIRFLOW_CTX_DAG_OWNER=***
AIRFLOW_CTX_DAG_ID=download_rocket_launches
AIRFLOW_CTX_TASK_ID=get_pictures
AIRFLOW_CTX_EXECUTION_DATE=2021-08-08T00:00:00+00:00
AIRFLOW_CTX_DAG_RUN_ID=scheduled__2021-08-08T00:00:00+00:00
[2021-08-22 14:48:44,859] {taskinstance.py:1501} ERROR - Task failed with exception
Traceback (most recent call last):
  File "/home/airflow/.local/lib/python3.6/site-packages/airflow/models/taskinstance.py", line 1157, in _run_raw_task
    self._prepare_and_execute_task_with_callbacks(context, task)
  File "/home/airflow/.local/lib/python3.6/site-packages/airflow/models/taskinstance.py", line 1331, in _prepare_and_execute_task_with_callbacks
    result = self._execute_task(context, task_copy)
  File "/home/airflow/.local/lib/python3.6/site-packages/airflow/models/taskinstance.py", line 1361, in _execute_task
    result = task_copy.execute(context=context)
  File "/home/airflow/.local/lib/python3.6/site-packages/airflow/operators/python.py", line 150, in execute
    return_value = self.execute_callable()
  File "/home/airflow/.local/lib/python3.6/site-packages/airflow/operators/python.py", line 161, in execute_callable
    return self.python_callable(*self.op_args, **self.op_kwargs)
  File "/opt/airflow/dags/1.rocket_launch_data.py", line 34, in _get_pictures
    launches = json.load(f)
  File "/usr/local/lib/python3.6/json/__init__.py", line 299, in load
    parse_constant=parse_constant, object_pairs_hook=object_pairs_hook, **kw)
  File "/usr/local/lib/python3.6/json/__init__.py", line 354, in loads
    return _default_decoder.decode(s)
  File "/usr/local/lib/python3.6/json/decoder.py", line 339, in decode
    obj, end = self.raw_decode(s, idx=_w(s, 0).end())
  File "/usr/local/lib/python3.6/json/decoder.py", line 355, in raw_decode
    obj, end = self.scan_once(s, idx)
json.decoder.JSONDecodeError: Unterminated string starting at: line 1 column 16379 (char 16378)
[2021-08-22 14:48:44,907] {taskinstance.py:1551} INFO - Marking task as FAILED. dag_id=download_rocket_launches, task_id=get_pictures, execution_date=20210808T000000, start_date=20210822T144843, end_date=20210822T144844
[2021-08-22 14:48:45,074] {local_task_job.py:149} INFO - Task exited with return code 1
